[2025-04-23T19:44:18.623+0000] {local_task_job_runner.py:123} INFO - ::group::Pre task execution logs
[2025-04-23T19:44:18.637+0000] {taskinstance.py:2612} INFO - Dependencies all met for dep_context=non-requeueable deps ti=<TaskInstance: full_etl_dbt_pipeline.run_dbt_transformations manual__2025-04-23T19:08:54.037348+00:00 [queued]>
[2025-04-23T19:44:18.643+0000] {taskinstance.py:2612} INFO - Dependencies all met for dep_context=requeueable deps ti=<TaskInstance: full_etl_dbt_pipeline.run_dbt_transformations manual__2025-04-23T19:08:54.037348+00:00 [queued]>
[2025-04-23T19:44:18.643+0000] {taskinstance.py:2865} INFO - Starting attempt 5 of 5
[2025-04-23T19:44:18.652+0000] {taskinstance.py:2888} INFO - Executing <Task(BashOperator): run_dbt_transformations> on 2025-04-23 19:08:54.037348+00:00
[2025-04-23T19:44:18.660+0000] {standard_task_runner.py:104} INFO - Running: ['***', 'tasks', 'run', 'full_etl_dbt_pipeline', 'run_dbt_transformations', 'manual__2025-04-23T19:08:54.037348+00:00', '--job-id', '246', '--raw', '--subdir', 'DAGS_FOLDER/run_dbt_pipeline.py', '--cfg-path', '/tmp/tmpertcjn8y']
[2025-04-23T19:44:18.664+0000] {standard_task_runner.py:105} INFO - Job 246: Subtask run_dbt_transformations
[2025-04-23T19:44:18.663+0000] {logging_mixin.py:190} WARNING - /home/***/.local/lib/python3.12/site-packages/***/task/task_runner/standard_task_runner.py:70 DeprecationWarning: This process (pid=3592) is multi-threaded, use of fork() may lead to deadlocks in the child.
[2025-04-23T19:44:18.665+0000] {standard_task_runner.py:72} INFO - Started process 3595 to run task
[2025-04-23T19:44:18.699+0000] {task_command.py:467} INFO - Running <TaskInstance: full_etl_dbt_pipeline.run_dbt_transformations manual__2025-04-23T19:08:54.037348+00:00 [running]> on host aab73994fc52
[2025-04-23T19:44:18.758+0000] {taskinstance.py:3131} INFO - Exporting env vars: AIRFLOW_CTX_DAG_OWNER='***' AIRFLOW_CTX_DAG_ID='full_etl_dbt_pipeline' AIRFLOW_CTX_TASK_ID='run_dbt_transformations' AIRFLOW_CTX_EXECUTION_DATE='2025-04-23T19:08:54.037348+00:00' AIRFLOW_CTX_TRY_NUMBER='5' AIRFLOW_CTX_DAG_RUN_ID='manual__2025-04-23T19:08:54.037348+00:00'
[2025-04-23T19:44:18.760+0000] {taskinstance.py:731} INFO - ::endgroup::
[2025-04-23T19:44:18.763+0000] {subprocess.py:63} INFO - Tmp dir root location: /tmp
[2025-04-23T19:44:18.764+0000] {subprocess.py:75} INFO - Running command: ['/usr/bin/bash', '-c', 'export PATH="$PATH:/home/***/.local/bin" && cd "$DBT_PROJECT_DIR" && dbt run --profiles-dir "$DBT_PROJECT_DIR/config" && dbt test --profiles-dir "$DBT_PROJECT_DIR/config" && dbt snapshot --profiles-dir "$DBT_PROJECT_DIR/config"']
[2025-04-23T19:44:18.773+0000] {subprocess.py:86} INFO - Output:
[2025-04-23T19:44:18.803+0000] {subprocess.py:93} INFO - Error processing line 2 of /home/***/.local/lib/python3.12/site-packages/sqlalchemy_spanner-1.7.0-py3.9-nspkg.pth:
[2025-04-23T19:44:18.804+0000] {subprocess.py:93} INFO - 
[2025-04-23T19:44:18.892+0000] {subprocess.py:93} INFO -   Traceback (most recent call last):
[2025-04-23T19:44:18.892+0000] {subprocess.py:93} INFO -     File "<frozen site>", line 206, in addpackage
[2025-04-23T19:44:18.893+0000] {subprocess.py:93} INFO -     File "<string>", line 1, in <module>
[2025-04-23T19:44:18.893+0000] {subprocess.py:93} INFO -     File "<frozen importlib._bootstrap>", line 810, in module_from_spec
[2025-04-23T19:44:18.893+0000] {subprocess.py:93} INFO -   AttributeError: 'NoneType' object has no attribute 'loader'
[2025-04-23T19:44:18.894+0000] {subprocess.py:93} INFO - 
[2025-04-23T19:44:18.894+0000] {subprocess.py:93} INFO - Remainder of file ignored
[2025-04-23T19:44:18.895+0000] {subprocess.py:93} INFO - Error processing line 2 of /home/***/.local/lib/python3.12/site-packages/sqlalchemy_spanner-1.7.0-py3.9-nspkg.pth:
[2025-04-23T19:44:18.896+0000] {subprocess.py:93} INFO - 
[2025-04-23T19:44:18.896+0000] {subprocess.py:93} INFO -   Traceback (most recent call last):
[2025-04-23T19:44:18.896+0000] {subprocess.py:93} INFO -     File "<frozen site>", line 206, in addpackage
[2025-04-23T19:44:18.896+0000] {subprocess.py:93} INFO -     File "<string>", line 1, in <module>
[2025-04-23T19:44:18.896+0000] {subprocess.py:93} INFO -     File "<frozen importlib._bootstrap>", line 810, in module_from_spec
[2025-04-23T19:44:18.897+0000] {subprocess.py:93} INFO -   AttributeError: 'NoneType' object has no attribute 'loader'
[2025-04-23T19:44:18.897+0000] {subprocess.py:93} INFO - 
[2025-04-23T19:44:18.897+0000] {subprocess.py:93} INFO - Remainder of file ignored
[2025-04-23T19:44:21.090+0000] {subprocess.py:93} INFO - [0m19:44:21  Running with dbt=1.9.4
[2025-04-23T19:44:21.961+0000] {subprocess.py:93} INFO - [0m19:44:21  Registered adapter: snowflake=1.9.2
[2025-04-23T19:44:21.996+0000] {subprocess.py:93} INFO - Error processing line 2 of /home/***/.local/lib/python3.12/site-packages/sqlalchemy_spanner-1.7.0-py3.9-nspkg.pth:
[2025-04-23T19:44:21.997+0000] {subprocess.py:93} INFO - 
[2025-04-23T19:44:22.084+0000] {subprocess.py:93} INFO -   Traceback (most recent call last):
[2025-04-23T19:44:22.086+0000] {subprocess.py:93} INFO -     File "<frozen site>", line 206, in addpackage
[2025-04-23T19:44:22.086+0000] {subprocess.py:93} INFO -     File "<string>", line 1, in <module>
[2025-04-23T19:44:22.086+0000] {subprocess.py:93} INFO -     File "<frozen importlib._bootstrap>", line 810, in module_from_spec
[2025-04-23T19:44:22.086+0000] {subprocess.py:93} INFO -   AttributeError: 'NoneType' object has no attribute 'loader'
[2025-04-23T19:44:22.087+0000] {subprocess.py:93} INFO - 
[2025-04-23T19:44:22.088+0000] {subprocess.py:93} INFO - Remainder of file ignored
[2025-04-23T19:44:22.088+0000] {subprocess.py:93} INFO - Error processing line 2 of /home/***/.local/lib/python3.12/site-packages/sqlalchemy_spanner-1.7.0-py3.9-nspkg.pth:
[2025-04-23T19:44:22.089+0000] {subprocess.py:93} INFO - 
[2025-04-23T19:44:22.091+0000] {subprocess.py:93} INFO -   Traceback (most recent call last):
[2025-04-23T19:44:22.091+0000] {subprocess.py:93} INFO -     File "<frozen site>", line 206, in addpackage
[2025-04-23T19:44:22.091+0000] {subprocess.py:93} INFO -     File "<string>", line 1, in <module>
[2025-04-23T19:44:22.091+0000] {subprocess.py:93} INFO -     File "<frozen importlib._bootstrap>", line 810, in module_from_spec
[2025-04-23T19:44:22.092+0000] {subprocess.py:93} INFO -   AttributeError: 'NoneType' object has no attribute 'loader'
[2025-04-23T19:44:22.092+0000] {subprocess.py:93} INFO - 
[2025-04-23T19:44:22.092+0000] {subprocess.py:93} INFO - Remainder of file ignored
[2025-04-23T19:44:22.478+0000] {subprocess.py:93} INFO - [0m19:44:22  Encountered an error:
[2025-04-23T19:44:22.478+0000] {subprocess.py:93} INFO - Compilation Error
[2025-04-23T19:44:22.480+0000] {subprocess.py:93} INFO -   dbt found two schema.yml entries for the same resource named stock_metrics. Resources and their associated columns may only be described a single time. To fix this, remove the resource entry for stock_metrics in one of these files:
[2025-04-23T19:44:22.480+0000] {subprocess.py:93} INFO -    - models/example/schema.yml
[2025-04-23T19:44:22.480+0000] {subprocess.py:93} INFO -   tests/not_null_stock_metrics.yml
[2025-04-23T19:44:23.242+0000] {subprocess.py:97} INFO - Command exited with return code 2
[2025-04-23T19:44:23.253+0000] {taskinstance.py:3310} ERROR - Task failed with exception
Traceback (most recent call last):
  File "/home/airflow/.local/lib/python3.12/site-packages/airflow/models/taskinstance.py", line 767, in _execute_task
    result = _execute_callable(context=context, **execute_callable_kwargs)
             ^^^^^^^^^^^^^^^^^^^^^^^^^^^^^^^^^^^^^^^^^^^^^^^^^^^^^^^^^^^^^
  File "/home/airflow/.local/lib/python3.12/site-packages/airflow/models/taskinstance.py", line 733, in _execute_callable
    return ExecutionCallableRunner(
           ^^^^^^^^^^^^^^^^^^^^^^^^
  File "/home/airflow/.local/lib/python3.12/site-packages/airflow/utils/operator_helpers.py", line 252, in run
    return self.func(*args, **kwargs)
           ^^^^^^^^^^^^^^^^^^^^^^^^^^
  File "/home/airflow/.local/lib/python3.12/site-packages/airflow/models/baseoperator.py", line 406, in wrapper
    return func(self, *args, **kwargs)
           ^^^^^^^^^^^^^^^^^^^^^^^^^^^
  File "/home/airflow/.local/lib/python3.12/site-packages/airflow/operators/bash.py", line 249, in execute
    raise AirflowException(
airflow.exceptions.AirflowException: Bash command failed. The command returned a non-zero exit code 2.
[2025-04-23T19:44:23.257+0000] {taskinstance.py:1225} INFO - Marking task as FAILED. dag_id=full_etl_dbt_pipeline, task_id=run_dbt_transformations, run_id=manual__2025-04-23T19:08:54.037348+00:00, execution_date=20250423T190854, start_date=20250423T194418, end_date=20250423T194423
[2025-04-23T19:44:23.267+0000] {taskinstance.py:340} INFO - ::group::Post task execution logs
[2025-04-23T19:44:23.268+0000] {standard_task_runner.py:124} ERROR - Failed to execute job 246 for task run_dbt_transformations (Bash command failed. The command returned a non-zero exit code 2.; 3595)
Traceback (most recent call last):
  File "/home/airflow/.local/lib/python3.12/site-packages/airflow/task/task_runner/standard_task_runner.py", line 117, in _start_by_fork
    ret = args.func(args, dag=self.dag)
          ^^^^^^^^^^^^^^^^^^^^^^^^^^^^^
  File "/home/airflow/.local/lib/python3.12/site-packages/airflow/cli/cli_config.py", line 49, in command
    return func(*args, **kwargs)
           ^^^^^^^^^^^^^^^^^^^^^
  File "/home/airflow/.local/lib/python3.12/site-packages/airflow/utils/cli.py", line 115, in wrapper
    return f(*args, **kwargs)
           ^^^^^^^^^^^^^^^^^^
  File "/home/airflow/.local/lib/python3.12/site-packages/airflow/cli/commands/task_command.py", line 483, in task_run
    task_return_code = _run_task_by_selected_method(args, _dag, ti)
                       ^^^^^^^^^^^^^^^^^^^^^^^^^^^^^^^^^^^^^^^^^^^^
  File "/home/airflow/.local/lib/python3.12/site-packages/airflow/cli/commands/task_command.py", line 256, in _run_task_by_selected_method
    return _run_raw_task(args, ti)
           ^^^^^^^^^^^^^^^^^^^^^^^
  File "/home/airflow/.local/lib/python3.12/site-packages/airflow/cli/commands/task_command.py", line 341, in _run_raw_task
    return ti._run_raw_task(
           ^^^^^^^^^^^^^^^^^
  File "/home/airflow/.local/lib/python3.12/site-packages/airflow/utils/session.py", line 97, in wrapper
    return func(*args, session=session, **kwargs)
           ^^^^^^^^^^^^^^^^^^^^^^^^^^^^^^^^^^^^^^
  File "/home/airflow/.local/lib/python3.12/site-packages/airflow/models/taskinstance.py", line 3004, in _run_raw_task
    return _run_raw_task(
           ^^^^^^^^^^^^^^
  File "/home/airflow/.local/lib/python3.12/site-packages/airflow/models/taskinstance.py", line 273, in _run_raw_task
    TaskInstance._execute_task_with_callbacks(
  File "/home/airflow/.local/lib/python3.12/site-packages/airflow/models/taskinstance.py", line 3158, in _execute_task_with_callbacks
    result = self._execute_task(context, task_orig)
             ^^^^^^^^^^^^^^^^^^^^^^^^^^^^^^^^^^^^^^
  File "/home/airflow/.local/lib/python3.12/site-packages/airflow/models/taskinstance.py", line 3182, in _execute_task
    return _execute_task(self, context, task_orig)
           ^^^^^^^^^^^^^^^^^^^^^^^^^^^^^^^^^^^^^^^
  File "/home/airflow/.local/lib/python3.12/site-packages/airflow/models/taskinstance.py", line 767, in _execute_task
    result = _execute_callable(context=context, **execute_callable_kwargs)
             ^^^^^^^^^^^^^^^^^^^^^^^^^^^^^^^^^^^^^^^^^^^^^^^^^^^^^^^^^^^^^
  File "/home/airflow/.local/lib/python3.12/site-packages/airflow/models/taskinstance.py", line 733, in _execute_callable
    return ExecutionCallableRunner(
           ^^^^^^^^^^^^^^^^^^^^^^^^
  File "/home/airflow/.local/lib/python3.12/site-packages/airflow/utils/operator_helpers.py", line 252, in run
    return self.func(*args, **kwargs)
           ^^^^^^^^^^^^^^^^^^^^^^^^^^
  File "/home/airflow/.local/lib/python3.12/site-packages/airflow/models/baseoperator.py", line 406, in wrapper
    return func(self, *args, **kwargs)
           ^^^^^^^^^^^^^^^^^^^^^^^^^^^
  File "/home/airflow/.local/lib/python3.12/site-packages/airflow/operators/bash.py", line 249, in execute
    raise AirflowException(
airflow.exceptions.AirflowException: Bash command failed. The command returned a non-zero exit code 2.
[2025-04-23T19:44:23.282+0000] {local_task_job_runner.py:266} INFO - Task exited with return code 1
[2025-04-23T19:44:23.296+0000] {taskinstance.py:3900} INFO - 0 downstream tasks scheduled from follow-on schedule check
[2025-04-23T19:44:23.297+0000] {local_task_job_runner.py:245} INFO - ::endgroup::
